Workbook

Sheet Instructions
B2: Ask AI — Tester Feedback Workbook
B3: SCEAI POC · https://askai.hmatechs.net · one row per finding · send back to Boss (or keep on the shared drive)
B5: How to test | C5: Use a FRESH chat for every question (click the logo to start over). Test in English AND Arabic, in both lenses (Executive Lens / Explore Data), and try the three agents: SCEAI Indicators, Oxford Economics, and Combined.
B6: Golden rule #1 | C6: Copy the EXACT question you typed into the 'Exact question' column — character for character, Arabic included. A paraphrase of your question is the #1 reason a finding cannot be reproduced.
B7: Golden rule #2 | C7: One row = one finding. If a card has three problems, that is three rows (repeat the question).
B8: Screenshots | C8: Take a screenshot of every finding. Name the file with the Finding ID (e.g. F-012.png) and put it in the shared screenshots folder, then set 'Screenshot?' = Yes.
B9: What counts | C9: Wrong or unexpected numbers · missing data you believe exists · comparison showing wrong countries · Arabic text/layout issues · confusing wording or design · slow answers · anything in the Oxford answer that looks implausible · ideas and suggestions — everything is welcome.
B10: Severity guide | C10: Blocker = cannot continue testing / demo would fail. Major = wrong or misleading content shown to the user. Minor = correct but awkward (wording, layout, latency). Cosmetic = purely visual polish. Idea = suggestion, not a defect.
B11: Expected latency | C11: 8–9 seconds per answer is NORMAL in this phase (known infrastructure item). Combined mode can take up to twice that. Only log latency findings that are far outside this.
B12: Known items (do not log) | C12: External (Oxford) figures are not verified against approved data — that is by design and labeled. Evidence rows deliberately show full precision while headlines round to 1 decimal. 2029 zeros for Import/Export Time are a known client-data issue.
B13: Columns you fill | C13: Everything from 'Date' to 'Reproducible?'. The grey columns on the right (Status, Fix version, Engineering notes) are for triage — please leave them.

Sheet Lists
A1: Language | B1: Agent | C1: Lens | D1: Category | E1: Severity | F1: YesNo | G1: Repro | H1: Status
A2: English | B2: SCEAI Indicators | C2: Executive Lens | D2: Wrong / unexpected answer | E2: Blocker | F2: Yes | G2: Always | H2: New
A3: Arabic | B3: Oxford Economics | C3: Explore Data | D3: Missing data | E3: Major | F3: No | G3: Sometimes | H3: Triaged
A4: Both | B4: Combined | D4: Numbers / rounding | E4: Minor | G4: Happened once | H4: In progress
D5: Chart | E5: Cosmetic | H5: Fixed
D6: Comparison / countries | E6: Idea | H6: Won't fix
D7: Arabic / RTL | H7: Duplicate
D8: Wording / labels | H8: Not reproducible
D9: UI / design
D10: Performance
D11: External (Oxford) content
D12: Login / access
D13: Suggestion / idea
D14: Other

Sheet Feedback Log
A1: Finding ID | B1: Date | C1: Language | D1: Exact question asked (copy–paste!) | E1: Category | F1: What happened (actual) | G1: What you expected | H1: Severity
A2: =IF(B2="","","F-"&TEXT(ROW()-1,"000")) -> F-001 | B2: 2026-08-15 | C2: Arabic | D2: قارن بين نسبة التضخم بين قطر وسنغافورة لسنة 2026 | E2: Comparison / countries | F2: The card showed 6 countries (Oman, Kuwait, KSA, Bahrain…) although I asked only for Qatar vs Singapore. | G2: Only Qatar and Singapore in the table and the chart. | H2: Major
A3: =IF(B3="","","F-"&TEXT(ROW()-1,"000")) -> F-002 | B3: 2026-08-15 | C3: English | D3: what is the GDP growth for 2026 | E3: External (Oxford) content | F3: Oxford section says forecast is -28.76% which cannot be right. | G3: A plausible forecast, or a warning on the figure. | H3: Major
A4: =IF(B4="","","F-"&TEXT(ROW()-1,"000")) -> F-003 | B4: 46259 | C4: English | D4: give me a chart of Qatar's GDP from 2022 to 2025 | E4: Chart | F4: "The indicator 'Value of VC deals directed to Qatar-based start-ups (as a % of GDP)' is marked inactive in the approved data. Do you still want to view it?" The system thinks I am asking about value of VC deals, and thus has warned me that the indicator is inactive. while the GDP indicator is in fact active | G4: a chart of Qatar's GDP from 2022 to 2025 | H4: Major
A5: =IF(B5="","","F-"&TEXT(ROW()-1,"000")) -> F-004 | B5: 46260 | C5: English | D5: give me a chart of Qatar's GDP from 2022 to 2025 | E5: Chart | F5: When the chart is produced, the number of significant figures on the numbers in the chart does not match the number of significant figures that we have in MFS. This might be confusing to leadership. Additionally, the chart in the chatbot does not capture the indicator unit. Two images have been added to show the comparison | G5: Charts should display the correct count of significant figures, per indicator, with the correct unit | H5: Minor
A6: =IF(B6="","","F-"&TEXT(ROW()-1,"000")) -> F-005 | B6: 46260 | C6: English | D6: what is the growth rate of Qatar's GDP from 2022 to 2025? | E6: Wrong / unexpected answer | F6: Multiple issues with this one, the system did not understand that the question referrs to annual values. Instead, it generated a full list of data points between Q1 2022 and Q4 2025, and simply calculated a growth percentage between the two points. Then, it proceeded to retreive the analyses associated with GDP for the year 2025, which was not asked for. Finally, when generating the numbers, what does the status amended mean? this breeds confusion and lack of trust for the reader. In a nutshell, the chatbot is not able to reason with the available data, it simply retreives it. | G6: Either a simple 2022 to 2025 average growth rate or a CAGR between the two years. | H6: Major
A7: =IF(B7="","","F-"&TEXT(ROW()-1,"000")) -> F-006 | B7: 46260 | C7: English | D7: how are the prices doing lately on a monthly basis? | E7: Wrong / unexpected answer | F7: The system returned quarterly data, despite the availability of monthly data | G7: the system should return monthly data with monthly comparisions, as per the question | H7: Major
A8: =IF(B8="","","F-"&TEXT(ROW()-1,"000")) -> F-007 | B8: 46260 | C8: English | D8: What's the latest in Qatar's economy? | E8: Missing data | F8: Multiple issues, the system does not understand that the user wants high level economic indicators to gauge the health of the economy (e.g. GDP, inflation, trade balance, etc.). Instead, it just retrieves the latest GDP value and its corresponding analysis, without providing any contextual understanding of how the economy is doing, leveraging the indicators in the database. | G8: A selection of macroeconomic indicators (e.g. GDP, inflation, trade balance, etc.) ordered by recency, and a few lines explaining what does it all mean. | H8: Major
A9: =IF(B9="","","F-"&TEXT(ROW()-1,"000")) -> F-008 | B9: 46260 | C9: English | D9: What was the highest quarterly GDP value recorded, and in which quarter? | E9: Wrong / unexpected answer | F9: The value provided is incorrect. The highest GDP value should be 186.0. However, the response returned 185.2, which corresponds to Q4 2025. | G9: I should got the value of the third quarter not the value for the forth quarter | H9: Major
A10: =IF(B10="","","F-"&TEXT(ROW()-1,"000")) -> F-009 | B10: 46260 | C10: English | D10: List Qatar’s quarterly GDP values for 2024 and 2025 and rank them from highest to lowest. | E10: Wrong / unexpected answer | F10: The system could not provide an answer | G10: List of GDP values for the 2024 and 2025 from the highest to the lowest | H10: Major
A11: =IF(B11="","","F-"&TEXT(ROW()-1,"000")) -> F-010 | B11: 46260 | C11: English | D11: What is the difference between the highest and lowest quarterly GDP values in the available data? | E11: Wrong / unexpected answer | F11: The system could not provide an answer | G11: The system should be able to substract the highest value from the lowest GDP value | H11: Major
A12: =IF(B12="","","F-"&TEXT(ROW()-1,"000")) -> F-011 | B12: 46260 | C12: English | D12: How did Qatar’s GDP change between Q1 2025 and Q4 2025? Provide the absolute value. | E12: Wrong / unexpected answer | F12: The system could not provide an answer | G12: The system provide the last data for Q4-2025 while I asked him about the changes between Q1-2025 and Q4-2025 | H12: Major
A13: =IF(B13="","","F-"&TEXT(ROW()-1,"000")) -> F-012 | B13: 46260 | C13: English | D13: What is the value of Nominal GDP in Q4-2025? | E13: Wrong / unexpected answer | F13: The system provide a wrong answer | G13: The system should not provide any data because what we have in the data in real GDP and not nominal and it's clear in the name of the indicator | H13: Major
A14: F-013 | B14: 46261 | C14: English | D14: How many GCC tourists arrived into Qatar in 2025? | E14: Performance | F14: I tried to trick the system by asking for an indicator that is not directly available. The SCEAI indicators answer generated relatively quickly, but the Oxford Economics answer took upwards of a minute to generate | G14: Answers should be generated within the expected timeframe noted in the instructions sheet | H14: Minor
A15: F-014 | B15: 46261 | C15: English | D15: How many tourists arrived into Qatar in May 2025? | E15: Wrong / unexpected answer | F15: The system was not able to recognize the indicator I'm referring to unless the name is an exact match (i.e. Number of international visitors) | G15: I expected the system to return the value of number of international visitors in May 2025, which is 2.297m visitors | H15: Major
A16: F-015 | B16: 46261 | C16: English | D16: How many international visitors arrived in Qatar in May 2025? | E16: Wrong / unexpected answer | F16: Multiple major issues in this one. This is a monthly cumilative indicator. The system returned the value for Q4 2025 which I did not ask for, and its wrong. It compared with Q1 2025 which is wrong. It Provided the analysis for december 2025, which is the wrong data point. and did a benchmark which cannot be found in MFS. Finally, the system noted that the monthly data is not available, only annual data is available, which is wrong. Everything provided in this answer is wrong. | G16: I expected the system to return the value of number of international visitors in May 2025, which is 2.297m visitors | H16: Major
A17: F-016 | B17: 46261 | C17: English | D17: what can you do? | E17: Wrong / unexpected answer | F17: While the system was able to answer a simple "hi", it was not to provide a simple summary of what it can do. Executive using the system for the first time will ask such questions | G17: I expected a summary of the AI's capabilities given the available data | H17: Major
A18: F17 | B18: 46261 | C18: English | D18: What is the GDP forecast 2026 | E18: Wrong / unexpected answer | F18: It did not provide the expected forecast as a percentage. Instead, it gave the value in Qatari riyals, and the value itself was also incorrect. | G18: I expected the answe to be -24.5% | H18: Major
A19: F-018 | B19: 46261 | C19: Arabic | D19: ما هو وضع الاقتصاد الحالي في الدولة؟ | E19: Missing data | F19: While the Oxford generated summary is more or less acceptable, the system was not able to understand that it needs to provide simple economic overview from SCEAI data (similar to ticket F-007) | G19: I expected the system to return some SCEAI indicators relevant to the overall economy (such as GDP, inflation, trade balance, etc.) | H19: Minor
A20: F19 | B20: 46261 | C20: Arabic | D20: ما هو أخر تحليل للتضخم | E20: Wrong / unexpected answer | F20: It stated that no official figures were available, even though such figures do exist, making the response misleading. | G20: I expected the system will return back to the inflation indeicator and the get the right answer. | H20: Major
A21: F-020 | B21: 46261 | C21: Arabic | D21: اعطني رسم بياني يوضح عدد السياح من خارج الدولة بشكل شهري مابين 2023 و 2024 | E21: Wrong / unexpected answer | F21: Same issues as ticket F-015, but in Arabic | G21: Technically the system provided a chart, but all the data around it was incorrect. | H21: Major
A22: F-021 | B22: 46261 | C22: Arabic | D22: هل هناك شركات تكنولوجيا ماليه جديدة تم افتتاحها في عام 2025؟ | E22: Wording / labels | F22: The system retrieved the full values for 2024 and 2025, and posted the corresponding analysis. This is not what I asked? | G22: The system should have checked the indicator value for 2024 and 2025, compared them, and simply returned "No, no new companies were opened in 2025". The answer that the system provided is technically correct, but I did not ask for all of this. | H22: Minor
A23: =IF(B23="","","F-"&TEXT(ROW()-1,"000")) -> F-022 | B23: 46264 | C23: English | D23: how has inflation changed over the last 5 years | E23: Wrong / unexpected answer | F23: The system retrieved Quartely data from 5 years, and did a QOQ change. | G23: Since the question mention last 5 years, it should have done the YoY change for the past years | H23: Major
A24: =IF(B24="","","F-"&TEXT(ROW()-1,"000")) -> F-023 | B24: 46264 | C24: English | D24: how has inflation changed over the last 3 years | E24: Wrong / unexpected answer | F24: The system retrieved Quartely data from 5 years, and did a QOQ change. | G24: Should have been for the lasat three years not five, and the value should be YoY change | H24: Major
A25: =IF(B25="","","F-"&TEXT(ROW()-1,"000")) -> F-024 | B25: 46264 | C25: English | D25: Show the trend of Inflation | E25: Wrong / unexpected answer | F25: 2025-Q3 and 2025-Q4 are skipped without explanation. | G25: Not correctly interpret a trend query. When asked to “Show the trend of Inflation,” it returns only the latest value and compares it against a non-consecutive historical period (2025-Q2), instead of retrieving and presenting the chronological time series. It should not have decided on quarterly at all unless the user asked for quarterly data or the indicator metadata explicitly defined quarterly as the default frequency, which in this case is monthly. | H25: Major
A26: =IF(B26="","","F-"&TEXT(ROW()-1,"000")) -> F-025 | B26: 46264 | C26: English | D26: Show the monthly trend of Inflation | E26: Wrong / unexpected answer | F26: Show the monthly trend of Inflation | G26: Same issue system decides to pick the starting interval randomly | H26: Major
A27: =IF(B27="","","F-"&TEXT(ROW()-1,"000")) -> F-026 | B27: 46264 | C27: English | D27: Compare Inflation in 2024-05 and 2026-04 | E27: Wrong / unexpected answer | F27: This response is incorrect because ASK AI ignored the comparison requested and switched to a country-ranking use case. The word “Compare” may be mapped too broadly to a predefined country comparison function. | G27: ASK AI should identify this as a period-to-period comparison for the same indicator and geography, retrieve the values for both specified periods, calculate the difference in percentage points, and provide a concise comparison. The comparison dimension should be derived from the entities explicitly provided in the user query rather than defaulting the word “compare” to country benchmarking. | H27: Major
A28: =IF(B28="","","F-"&TEXT(ROW()-1,"000")) -> F-027 | B28: 46264 | C28: English | D28: which country had the lowest inflation | E28: Wrong / unexpected answer | F28: the question asks for a country comparison, but ASK AI answered with the lowest historical inflation value for one country/time series. | G28: Maybe ASK AI should have done a follow up questions : " for which period?" ASK AI should compare Inflation values across available countries for a common period and identify the country with the lowest value. Where no period is specified, the system should either use the latest common comparable period and clearly state it, or request the period if required by the business rules. | H28: Major
A29: =IF(B29="","","F-"&TEXT(ROW()-1,"000")) -> F-028 | B29: 46264 | C29: English | D29: Analyst Summary should be Summary Analysis | E29: Wrong / unexpected answer | H29: Cosmetic
A30: =IF(B30="","","F-"&TEXT(ROW()-1,"000")) -> F-029 | B30: 46264 | C30: English | D30: Show GDP growth, inflation, and government revenues | E30: Wrong / unexpected answer | F30: For GDP Growth: ASK AI could calculate YoY or QoQ growth from Real GDP, but it must label exactly which growth rate it calculated. Inflation: Monthly and quarterly Inflation observations are being mixed within the same answer without a defined frequency-selection rule. April 2026 is later than Q1 2026. Therefore,3.0% for Q1 cannot simultaneously be presented as the latest value. The answer should have been for the same common periods. The response introduced comparisons against 2019-Q1 even though no historical comparison was requested. | G30: ASK AI should resolve each requested metric to the correct indicator, retrieve the appropriate latest approved observation based on defined frequency rules, and present the requested indicators concisely. Where different indicators have different latest reporting periods, these periods should be clearly shown. The system should not introduce historical comparison periods unless requested A Simple answer before it goes in details for ecample: Real GDP Growth: 2.9% YoY - 2025 Inflation: 2.6% YoY - Apr 2026 Government Revenues: QAR 37.8bn - Q1 2026 or even better: Real GDP Growth: 2.9% YoY - Q1 2026 Inflation: 2.6% YoY - Q1 2026 Government Revenues: QAR 37.8bn - Q1 2026 | H30: Major
A31: =IF(B31="","","F-"&TEXT(ROW()-1,"000")) -> F-030 | B31: 46264 | C31: English | D31: What does non-hydrocarbon GDP mean?” WHAT IS THE LATEST VALUE? WHAT about the last year? | E31: Wrong / unexpected answer | F31: Frist question response was correct, second questions moved into showing the value of Public Debt as a percetage of GDP, an indicator not requested. Followup questions or loss in context. Third quetion: atleast the answer should have retured with last year value for Pubic Debt instead the response: Nothing in the approved data matches “what about last year”. | G31: Context and follow up questions arent lost. | H31: Major
A32: =IF(B32="","","F-"&TEXT(ROW()-1,"000")) -> F-031 | B32: 46264 | C32: English | D32: Why did inflation fall to 0.2%?” when it did not | E32: Wrong / unexpected answer | F32: it returned the standard Inflation indicator card rather than informing the user that the available approved data does not support the stated value. | G32: Inflation did not fall to 0.2% in the available approved data. The latest available value is 2.6% YoY for April 2026. It declined from 4.2% in March 2026 to 2.6% in April 2026, a decrease of 1.6 percentage points. | H32: Major
A33: =IF(B33="","","F-"&TEXT(ROW()-1,"000")) -> F-032 | B33: 46264 | C33: English | D33: how many indicators in diversification target | E33: Wrong / unexpected answer | F33: Random anser please refer to screenshot | G33: The answer should be 12, and the names, ideally with the latest values. | H33: Major
A34: =IF(B34="","","F-"&TEXT(ROW()-1,"000")) -> F-033 | B34: 46264 | C34: English | D34: give me all the indicator names for the education sector | F34: Random anser please refer to screenshot | H34: Major
A35: =IF(B35="","","F-"&TEXT(ROW()-1,"000")) -> F-034 | B35: 46264 | C35: English | D35: List the indicators in Sectors | E35: UI / design | F35: Lists all indicators in the sector | G35: Should be listed professionally | H35: Major
A36: =IF(B36="","","F-"&TEXT(ROW()-1,"000")) -> F-035 | B36: 46264 | C36: English | D36: what is the inflation rate in Qatar in 2026 to be shown as a chart not figures only | F36: SCEAI answer has a call to action of download chart but not chart shown when clicked. On Oxford response I got this response: According to Oxford Economics, the forecasted inflation rate in Qatar for the year 2026 is 2.05%. However, please note that a chart cannot be provided in this format. | G36: chart
A37: =IF(B37="","","F-"&TEXT(ROW()-1,"000")) | C37: English | D37: Picture | F37: Oxford answers provide reasoning - SCEAI answers are totally unintelligent | G37: rationale
A38: =IF(B38="","","F-"&TEXT(ROW()-1,"000")) | C38: English | F38: SCEAI answers are only related to indicators without any reasoning at all - totally different than OE responses | G38: rationale
A39: =IF(B39="","","F-"&TEXT(ROW()-1,"000"))
A40: =IF(B40="","","F-"&TEXT(ROW()-1,"000"))
...

Sheet Test Ideas
A1: Area | B1: Try this question | C1: What a correct answer looks like | D1: OK? (Yes/No) | E1: Finding ID if not
A2: Latest value | B2: What is Qatar's latest GDP? | C2: Card with hero number 736.6 bn QAR (2025), green ▲ pill, analyst summary block, evidence rows with exact values.
A3: Latest value (AR) | B3: ما هو أحدث ميزان تجاري؟ | C3: Arabic card, readable numbers, Arabic labels throughout.
A4: Paraphrase | B4: How big is Qatar's economy right now? | C4: Resolves to Real GDP and answers — no 'figures can only be shown…' message.
A5: Paraphrase | B5: What are prices doing lately? | C5: Resolves to Inflation and answers.
A6: Two countries | B6: compare the inflation between qatar and singapore | C6: EXACTLY 2 rows (Qatar 2.6, Singapore 1.8), chart matches the table.
A7: Named countries | B7: Is inflation here higher than in Saudi and Kuwait? | C7: Exactly 3 rows: Qatar, KSA, Kuwait.
A8: GCC group | B8: compare the inflation between qatar and GCC | C8: 5 rows, — GCC in the title, Scope chip, NO Singapore, honest UAE line (latest available 2025).
A9: GCC group (AR) | B9: قارن معدل التضخم بين قطر ودول مجلس التعاون | C9: Same as above in Arabic with Arabic country names.
A10: Honesty — no data | B10: compare inflation between qatar and japan | C10: Qatar row + 'No approved data for Japan for this indicator.' — never an invented number.
A11: Honesty — no rank | B11: ما هو ترتيب قطر بين دول مجلس التعاون من حيث الناتج المحلي الإجمالي؟ | C11: Honest refusal — there is no GDP ranking indicator; no substitute card.
A12: Ranking | B12: Where does Qatar rank on the World Competitiveness Index? | C12: Places-language ('9 to 11'), integer ranks, 'among benchmark countries' wording, no % signs.
A13: Rounding | B13: What is Qatar's trade balance? | C13: Headline numbers with 1 decimal (177.4); evidence rows keep full precision (177.429) — this difference is intentional.
... A17: Lenses | B17: (ask anything, then flip the toggle) | C17: Executive Lens = short briefing (hero + summary + follow-ups). Explore Data = full detail (chart, What changed, detailed analysis, related).

Sheet Summary
B2: Triage summary (auto)
B4: By severity | E4: By status
B5: Blocker | C5: =COUNTIFS('Feedback Log'!$H$2:$H$400,B5,'Feedback Log'!$B$2:$B$400,"<>") -> 0 | E5: New | F5: =COUNTIFS('Feedback Log'!#REF!,E5,'Feedback Log'!$B$2:$B$400,"<>") -> #REF!
B6: Major | C6: =COUNTIFS('Feedback Log'!$H$2:$H$400,B6,'Feedback Log'!$B$2:$B$400,"<>") -> 29 | E6: Triaged | F6: =COUNTIFS('Feedback Log'!#REF!,E6,'Feedback Log'!$B$2:$B$400,"<>") -> #REF!
B7: Minor | C7: =COUNTIFS('Feedback Log'!$H$2:$H$400,B7,'Feedback Log'!$B$2:$B$400,"<>") -> 4 | E7: In progress | F7: =COUNTIFS('Feedback Log'!#REF!,E7,'Feedback Log'!$B$2:$B$400,"<>") -> #REF!
B8: Cosmetic | C8: =COUNTIFS('Feedback Log'!$H$2:$H$400,B8,'Feedback Log'!$B$2:$B$400,"<>") -> 1 | E8: Fixed | F8: =COUNTIFS('Feedback Log'!#REF!,E8,'Feedback Log'!$B$2:$B$400,"<>") -> #REF!
B9: Idea | C9: =COUNTIFS('Feedback Log'!$H$2:$H$400,B9,'Feedback Log'!$B$2:$B$400,"<>") -> 0 | E9: Won't fix | F9: =COUNTIFS('Feedback Log'!#REF!,E9,'Feedback Log'!$B$2:$B$400,"<>") -> #REF!
E10: Duplicate | F10: =COUNTIFS('Feedback Log'!#REF!,E10,'Feedback Log'!$B$2:$B$400,"<>") -> #REF!
E11: Not reproducible | F11: =COUNTIFS('Feedback Log'!#REF!,E11,'Feedback Log'!$B$2:$B$400,"<>") -> #REF!
B13: Total findings | C13: =COUNTIF('Feedback Log'!$B$2:$B$400,"<>") -> 35
B15: Open (not Fixed / Won't fix / Duplicate) | C15: =C13-SUMPRODUCT(COUNTIFS('Feedback Log'!#REF!,{"Fixed","Won't fix","Duplicate"},'Feedback Log'!$B$2:$B$400,"<>")) -> #REF!
